Workbook
Name Slicer_Incidents: #N/A
Name Slicer_Years__Date: #N/A

Sheet Data
C3: Date | D3: YearEvaluated | E3: Incidents | F3: Snake | G3: Elephant | H3: Wild Boar | I3: Wild Gaur | J3: Tiger | K3: Leopard | L3: Others | M3: ForestAreaLossHectare | N3: ForestArea | P3: Date | Q3: YearEvaluated | R3: Tigers | U3: Date | V3: YearEvaluated | W3: Wayand | X3: Nilambur | Y3: Anamudi | Z3: Periyar | AA3: Elephants | AC3: Sl._x000D_ No. | AD3: Species | AE3: No. of animals (1993) | AF3: No. of animals (1997) | AG3: No. of animals (2002) | AH3: No. of animals (2011) | AJ3: Sl._x000D_ No. | AK3: Species | AL3: No. of animals (1993) | AM3: No. of animals (1997) | AN3: No. of animals (2002) | AO3: No. of animals (2011)
C4: =DATE(D4,1,1) -> 43101 | D4: 2018 | E4: Human Death | F4: 92 | G4: 21 | H4: 3 | I4: 1 | J4: 2 | K4: 0 | L4: 0 | M4: 199.18667 | N4: 21144.29 | P4: =DATE(Data!$Q4,1,1) -> 35431 | Q4: 1997 | R4: 73 | U4: =DATE(Data!$V4,1,1) -> 38353 | V4: 2005 | W4: 882 | X4: 334 | Y4: 2299 | Z4: 1620 | AA4: =SUM(W4:Z4) -> 5135 | AC4: 1 | AD4: Wild Gaur | AE4: 4840 | AF4: 4151 | AG4: 14787 | AH4: 17860 | AJ4: 6 | AK4: Wild Boar | AL4: 40963 | AM4: 40425 | AN4: 60940 | AO4: 48034
C5: =DATE(D5,1,1) -> 43101 | D5: 2018 | E5: Human Injured | F5: 649 | G5: 45 | H5: 103 | I5: 3 | J5: 12 | K5: 1 | L5: 33 | M5: 199.18667 | N5: 21144.29 | P5: =DATE(Data!$Q5,1,1) -> 37257 | Q5: 2002 | R5: 71 | U5: =DATE(Data!$V5,1,1) -> 39083 | V5: 2007 | W5: 1240 | X5: 663 | Y5: 2505 | Z5: 1660 | AA5: =SUM(W5:Z5) -> 6068
C6: =DATE(D6,1,1) -> 43101 | D6: 2018 | E6: Cattle Death | F6: 15 | G6: 166 | H6: 1 | I6: 2 | J6: 97 | K6: 192 | L6: 88 | M6: 199.18667 | N6: 21144.29 | P6: =DATE(Data!$Q6,1,1) -> 38718 | Q6: 2006 | R6: 46 | U6: =DATE(Data!$V6,1,1) -> 40179 | V6: 2010 | W6: 1155 | X6: 1044 | Y6: 2220 | Z6: 1758 | AA6: =SUM(W6:Z6) -> 6177
C7: =DATE(D7,1,1) -> 43101 | D7: 2018 | E7: Crop and Property | F7: 0 | G7: 3236 | H7: 1194 | I7: 4 | J7: 190 | K7: 7 | L7: 1072 | M7: 199.18667 | N7: 21144.29 | P7: =DATE(Data!$Q7,1,1) -> 40179 | Q7: 2010 | R7: 71 | U7: =DATE(Data!$V7,1,1) -> 40909 | V7: 2012 | W7: 1483 | X7: 647 | Y7: 2086 | Z7: 1810 | AA7: =SUM(W7:Z7) -> 6026
C8: =DATE(D8,1,1) -> 43466 | D8: 2019 | E8: Human Death | F8: 71 | G8: 13 | H8: 3 | I8: 0 | J8: 2 | K8: 0 | L8: 3 | M8: 594.68218 | N8: 11520.058 | P8: =DATE(Data!$Q8,1,1) -> 41640 | Q8: 2014 | R8: 136 | U8: =DATE(Data!$V8,1,1) -> 42736 | V8: 2017 | Z8: 5706 | AA8: =SUM(W8:Z8) -> 5706
C9: =DATE(D9,1,1) -> 43466 | D9: 2019 | E9: Human Injured | F9: 548 | G9: 34 | H9: 97 | I9: 3 | J9: 0 | K9: 1 | L9: 16 | M9: 594.68218 | N9: 11520.058 | P9: =DATE(Data!$Q9,1,1) -> 43101 | Q9: 2018 | R9: 190 | U9: =DATE(Data!$V9,1,1) -> 44927 | V9: 2023 | Z9: 2386 | AA9: =SUM(W9:Z9) -> 2386
C10: =DATE(D10,1,1) -> 43466 | D10: 2019 | E10: Cattle Death | F10: 23 | G10: 0 | H10: 3 | I10: 0 | J10: 84 | K10: 96 | L10: 115 | M10: 594.68218 | N10: 11520.058 | P10: =DATE(Data!$Q10,1,1) -> 44562 | Q10: 2022 | R10: 213
C11: =DATE(D11,1,1) -> 43466 | D11: 2019 | E11: Crop and Property | F11: 0 | G11: 2848 | H11: 1250 | I11: 47 | J11: 0 | K11: 17 | L11: 1386 | M11: 594.68218 | N11: 11520.058
C12: =DATE(D12,1,1) -> 43831 | D12: 2020 | E12: Human Death | F12: 52 | G12: 27 | H12: 8 | I12: 0 | J12: 1 | K12: 0 | L12: 0 | M12: 244.8928 | N12: 11521.993
C13: =DATE(D13,1,1) -> 43831 | D13: 2020 | E13: Human Injured | F13: 767 | G13: 34 | H13: 146 | I13: 2 | J13: 0 | K13: 0 | L13: 39 | M13: 244.8928 | N13: 11521.993
C14: =DATE(D14,1,1) -> 43831 | D14: 2020 | E14: Cattle Death | F14: 27 | G14: 1 | H14: 3 | I14: 0 | J14: 141 | K14: 164 | L14: 64 | M14: 244.8928 | N14: 11521.993
C15: =DATE(D15,1,1) -> 43831 | D15: 2020 | E15: Crop and Property | F15: 0 | G15: 2945 | H15: 1898 | I15: 58 | J15: 23 | K15: 7 | L15: 1610 | M15: 244.8928 | N15: 11521.993
C16: =DATE(D16,1,1) -> 44197 | D16: 2021 | E16: Human Death | F16: 65 | G16: 35 | H16: 6 | I16: 3 | J16: 1 | K16: 0 | L16: 4 | M16: 83.294976 | N16: 11521.993
C17: =DATE(D17,1,1) -> 44197 | D17: 2021 | E17: Human Injured | F17: 547 | G17: 44 | H17: 127 | I17: 3 | J17: 0 | K17: 1 | L17: 36 | M17: 83.294976 | N17: 11524.913
C18: =DATE(D18,1,1) -> 44197 | D18: 2021 | E18: Cattle Death | F18: 33 | G18: 9 | H18: 3 | I18: 1 | J18: 179 | K18: 180 | L18: 109 | M18: 83.294976 | N18: 11524.913
C19: =DATE(D19,1,1) -> 44197 | D19: 2021 | E19: Crop and Property | F19: 0 | G19: 3349 | H19: 1737 | I19: 75 | J19: 24 | K19: 0 | L19: 1395 | M19: 83.294976 | N19: 11524.913
C20: =DATE(D20,1,1) -> 44562 | D20: 2022 | E20: Human Death | F20: 48 | G20: 27 | H20: 7 | I20: 1 | J20: 1 | K20: 0 | L20: 14 | M20: 219.66955 | N20: 11524.913
C21: =DATE(D21,1,1) -> 44562 | D21: 2022 | E21: Human Injured | F21: 871 | G21: 71 | H21: 261 | I21: 5 | J21: 0 | K21: 0 | L21: 67 | M21: 219.66955 | N21: 11531.908
C22: =DATE(D22,1,1) -> 44562 | D22: 2022 | E22: Cattle Death | F22: 65 | G22: 8 | H22: 4 | I22: 1 | J22: 191 | K22: 244 | L22: 124 | M22: 219.66955 | N22: 11531.908
... C27: =DATE(D27,1,1) -> 44927 | D27: 2023 | E27: Crop and Property | F27: 0 | G27: 4087 | H27: 1252 | I27: 25 | J27: 1 | K27: 0 | L27: 1498 | M27: 189.01569 | N27: 22059.36

Sheet Pivot
B2: Year | C2: Snakes | D2: Elephants | E2: Wild Boars | F2: Wild Gaurs | G2: Tigers | H2: Leopards | I2: Other
B3: Cattle Death | C3: 228 | D3: 192 | E3: 18 | F3: 5 | G3: 883 | H3: 1120 | I3: 624
B4: Crop and Property | C4: 0 | D4: 20552 | E4: 8583 | F4: 234 | G4: 239 | H4: 31 | I4: 8459
B5: Human Death | C5: 376 | D5: 150 | E5: 34 | F5: 6 | G5: 8 | H5: 0 | I5: 35
B6: Human Injured | C6: 4253 | D6: 299 | E6: 995 | F6: 21 | G6: 12 | H6: 3 | I6: 258
B7: Grand Total | C7: 4857 | D7: 21193 | E7: 9630 | F7: 266 | G7: 1142 | H7: 1154 | I7: 9376
B9: Year | C9: Snakes | D9: Elephants | E9: Wild Boars | F9: Wild Gaurs | G9: Tigers | H9: Leopards | I9: Other
B10: 2018 | C10: 756 | D10: 3468 | E10: 1301 | F10: 10 | G10: 301 | H10: 200 | I10: 1193
B11: 2019 | C11: 642 | D11: 2895 | E11: 1353 | F11: 50 | G11: 86 | H11: 114 | I11: 1520
B12: 2020 | C12: 846 | D12: 3007 | E12: 2055 | F12: 60 | G12: 165 | H12: 171 | I12: 1713
B13: 2021 | C13: 645 | D13: 3437 | E13: 1873 | F13: 82 | G13: 204 | H13: 181 | I13: 1544
B14: 2022 | C14: 984 | D14: 4193 | E14: 1524 | F14: 32 | G14: 193 | H14: 244 | I14: 1703
B15: 2023 | C15: 984 | D15: 4193 | E15: 1524 | F15: 32 | G15: 193 | H15: 244 | I15: 1703
B16: Grand Total | C16: 4857 | D16: 21193 | E16: 9630 | F16: 266 | G16: 1142 | H16: 1154 | I16: 9376
B19: Row Labels | C19: Forest Area
B20: 2018 | C20: 84577.16
B21: 2019 | C21: 46080.232
B22: 2020 | C22: 46087.972
B23: 2021 | C23: 46096.732
B24: 2022 | C24: 46120.637
B25: 2023 | C25: 88237.44
B26: Grand Total | C26: 357200.17
B29: Year | C29: Forest Area Loss
B30: 2018 | C30: 796.74668
B31: 2019 | C31: 2378.7287
B32: 2020 | C32: 979.57121
B33: 2021 | C33: 333.1799
B34: 2022 | C34: 878.6782
B35: 2023 | C35: 756.06274
B36: Grand Total | C36: 6122.9675
B39: Year | C39: Tigers Population
B40: 1997 | C40: 73
B41: 2002 | C41: 71
B42: 2006 | C42: 46
B43: 2010 | C43: 71
B44: 2014 | C44: 136
B45: 2018 | C45: 190
B46: 2022 | C46: 213
B47: Grand Total | C47: 800
B49: Row Labels | C49: Elephants Population
...

Sheet Dashboard

Sheet Insights
B2: INSIGHTS
A3: 1 | B3: Increase in wild life attacks from during the recent years.
A4: 2 | B4: Decrease in forest area , but increase in forest area in past years
A5: 3 | B5: Even though forest area is increased there is decrease in Tree covered area in forest
A6: 4 | B6: Increase in tiger population. Aged or injured look for domestic animals or humans.
A7: 5 | B7: Elephant population decreased in recent years around 50% , due to epidemic disesase spread among elephants sounthern states. But may be due the epidemic they are moving out of forest area and showing more violent behaviour.
A8: 6 | B8: Though exact figure not released by forest deparment , the population of wild boar and wild goar as increasing (news articles) , human conflict is increasing.

Sheet CorrectiveMeasures
B2: CORRECTIVE MEASURES
A3: 1 | B3: Increase Forest Area
A4: 2 | B4: Correct forest tree loss and vegetation which was lost during past years. Around 4.8 % of Total tree loss reported past 20 years.
A5: 3 | B5: Tiger population increased.Aged or Injured tigers which are not able to hunt should treated moved to zoological parks or reserved areas where food is available. This shoukd be done to prevent attack on easy targets such as domestic animals and humans.
A6: 4 | B6: To find cure for epidemic disease spreading among elephants , prevent extinction of wild elephants within the state.
A7: 5 | B7: Proper preventive measures to avoid attack of Wild Boar and Wild Gaur on agriculture areas and human life as there population keeps on increasing.

Sheet References
B2: REFERENCES
B3: https://forest.kerala.gov.in/en/home/
B4: https://kdisc.kerala.gov.in/wp-content/uploads/2024/12/Safe-Habitat-Hack.pdf
B5: https://www.globalforestwatch.org/dashboards/country/IND/17/
